<?xml version='1.0'?>
<sdf version='1.3'>
  <model name="tank_tread">
    <link name='chassis'>
      <pose>0 0 .13 0 0 0</pose>
      <collision name='collision'>
        <geometry>
          <box>
            <size>.25 .18 .13</size>
          </box>
        </geometry>
      </collision>

      <visual name='visual'>
        <geometry>
          <box>
            <size>.25 .18 .13</size>
          </box>
        </geometry>
      </visual>
    </link> 
  
  <link name="left_backwheel">
  	<pose>-0.125 0.115 0.13 0 1.5707 1.5707</pose>
    <collision name="collision">
      <geometry>
        <cylinder>
          <radius>.13</radius>
          <length>.05</length>
        </cylinder>
      </geometry>
    </collision>
    <visual name="visual">
      <geometry>
        <cylinder>
          <radius>.13</radius>
          <length>.05</length>
        </cylinder>
      </geometry>
    </visual>
  </link>
  
  <link name="right_backwheel">
  	<pose>-0.125 -0.115 0.13 0 1.5707 1.5707</pose>
    <collision name="collision">
      <geometry>
        <cylinder>
          <radius>.13</radius>
          <length>.05</length>
        </cylinder>
      </geometry>
    </collision>
    <visual name="visual">
      <geometry>
        <cylinder>
          <radius>.13</radius>
          <length>.05</length>
        </cylinder>
      </geometry>
    </visual>
  </link>
  
  
  <link name="left_frontwheel">
  	<pose>0.125 0.115 0.13 0 1.5707 1.5707</pose>
    <collision name="collision">
      <geometry>
        <cylinder>
          <radius>.13</radius>
          <length>.05</length>
        </cylinder>
      </geometry>
    </collision>
    <visual name="visual">
      <geometry>
        <cylinder>
          <radius>.13</radius>
          <length>.05</length>
        </cylinder>
      </geometry>
    </visual>
  </link>

  <link name="right_frontwheel">
  	<pose>0.125 -0.115 0.13 0 1.5707 1.5707</pose>
    <collision name="collision">
      <geometry>
        <cylinder>
          <radius>.13</radius>
          <length>.05</length>
        </cylinder>
      </geometry>
    </collision>
    <visual name="visual">
      <geometry>
        <cylinder>
          <radius>.13</radius>
          <length>.05</length>
        </cylinder>
      </geometry>
    </visual>
  </link>  


  <joint type="revolute" name="left_backwheel_hinge">
    <pose>0 0 0 0 0 0</pose>
    <child>left_backwheel</child>
    <parent>chassis</parent>
    <axis>
      <xyz>0 1 0</xyz>
    </axis>
  </joint>

  <joint type="revolute" name="left_frontwheel_hinge">
    <pose>0 0 0 0 0 0</pose>
    <child>left_frontwheel</child>
    <parent>chassis</parent>
    <axis>
      <xyz>0 1 0</xyz>
    </axis>
  </joint>
  
  <joint type="revolute" name="right_backwheel_hinge">
    <pose>0 0 0 0 0 0</pose>
    <child>right_backwheel</child>
    <parent>chassis</parent>
    <axis>
      <xyz>0 1 0</xyz>
    </axis>
  </joint>

  <joint type="revolute" name="right_frontwheel_hinge">
    <pose>0 0 0 0 0 0</pose>
    <child>right_frontwheel</child>
    <parent>chassis</parent>
    <axis>
      <xyz>0 1 0</xyz>
    </axis>
  </joint>
  
  </model>
</sdf>
