<?xml version='1.0'?>
<sdf version='1.3'>
  <model name="tank_tread2">
  
    <link name='chassis'>
      <pose>0 0 0.035 0 0 0</pose>
      <collision name='collision'>
        <geometry>
          <box>
            <size>0.13 0.18 0.0445</size>
          </box>
        </geometry>
      </collision>
      <visual name='visual'>
        <geometry>
          <box>
            <size>0.13 0.18 0.0445</size>
          </box>
        </geometry>
      </visual>
    </link> 

    <link name='plate'>
      <pose>-0.01 0 0.111 0 0 0</pose>
      <collision name='collision'>
        <geometry>
          <box>
            <size>0.10 0.10 0.02</size>
          </box>
        </geometry>
      </collision>
      <visual name='visual'>
        <geometry>
          <box>
            <size>0.10 0.10 0.02</size>
          </box>
        </geometry>
      </visual>
    </link> 
    
    <link name='plate_pole1'>
      <pose>0.035 0.045 0.088125 0 0 0</pose>
      <collision name='collision'>
        <geometry>
          <cylinder>
          	<radius>0.003</radius>
          	<length>0.06</length>
          </cylinder>
        </geometry>
      </collision>
      <visual name='visual'>
        <geometry>
          <cylinder>
          	<radius>0.003</radius>
          	<length>0.06</length>
          </cylinder>
        </geometry>
      </visual>
    </link> 

    <link name='plate_pole2'>
      <pose>0.035 -0.045 0.088125 0 0 0</pose>
      <collision name='collision'>
        <geometry>
          <cylinder>
          	<radius>0.003</radius>
          	<length>0.06</length>
          </cylinder>
        </geometry>
      </collision>
      <visual name='visual'>
        <geometry>
          <cylinder>
          	<radius>0.003</radius>
          	<length>0.06</length>
          </cylinder>
        </geometry>
      </visual>
    </link> 

    <link name='plate_pole3'>
      <pose>-0.055 0.045 0.088125 0 0 0</pose>
      <collision name='collision'>
        <geometry>
          <cylinder>
          	<radius>0.003</radius>
          	<length>0.06</length>
          </cylinder>
        </geometry>
      </collision>
      <visual name='visual'>
        <geometry>
          <cylinder>
          	<radius>0.003</radius>
          	<length>0.06</length>
          </cylinder>
        </geometry>
      </visual>
    </link> 

    <link name='plate_pole4'>
      <pose>-0.055 -0.045 0.088125 0 0 0</pose>
      <collision name='collision'>
        <geometry>
          <cylinder>
          	<radius>0.003</radius>
          	<length>0.06</length>
          </cylinder>
        </geometry>
      </collision>
      <visual name='visual'>
        <geometry>
          <cylinder>
          	<radius>0.003</radius>
          	<length>0.06</length>
          </cylinder>
        </geometry>
      </visual>
    </link> 
    
  
  <link name="left_backwheel">
  	<pose>-0.065 0.115 0.035 0 1.5707 1.5707</pose>
    <collision name="collision">
      <geometry>
        <cylinder>
          <radius>.05</radius>
          <length>.05</length>
        </cylinder>
      </geometry>
    </collision>
    <visual name="visual">
      <geometry>
        <cylinder>
          <radius>.05</radius>
          <length>.05</length>
        </cylinder>
      </geometry>
    </visual>
  </link>
  
  <link name="right_backwheel">
  	<pose>-0.065 -0.115 0.035 0 1.5707 1.5707</pose>
    <collision name="collision">
      <geometry>
        <cylinder>
          <radius>.05</radius>
          <length>.05</length>
        </cylinder>
      </geometry>
    </collision>
    <visual name="visual">
      <geometry>
        <cylinder>
          <radius>.05</radius>
          <length>.05</length>
        </cylinder>
      </geometry>
    </visual>
  </link>
  
  <link name="left_frontwheel">
  	<pose>0.065 0.115 0.035 0 1.5707 1.5707</pose>
    <collision name="collision">
      <geometry>
        <cylinder>
          <radius>.05</radius>
          <length>.05</length>
        </cylinder>
      </geometry>
    </collision>
    <visual name="visual">
      <geometry>
        <cylinder>
          <radius>.05</radius>
          <length>.05</length>
        </cylinder>
      </geometry>
    </visual>
  </link>

  <link name="right_frontwheel">
  	<pose>0.065 -0.115 0.035 0 1.5707 1.5707</pose>
    <collision name="collision">
      <geometry>
        <cylinder>
          <radius>.05</radius>
          <length>.05</length>
        </cylinder>
      </geometry>
    </collision>
    <visual name="visual">
      <geometry>
        <cylinder>
          <radius>.05</radius>
          <length>.05</length>
        </cylinder>
       </geometry>
    </visual>
  </link>
  
  <link name="left_topwheel">
  	<pose>-0.03 0.115 0.12 0 1.5707 1.5707</pose>
    <collision name="collision">
      <geometry>
        <cylinder>
          <radius>.03</radius>
          <length>.05</length>
        </cylinder>
      </geometry>
    </collision>
    <visual name="visual">
      <geometry>
        <cylinder>
          <radius>.03</radius>
          <length>.05</length>
        </cylinder>
      </geometry>
    </visual>
  </link>

  <link name="right_topwheel">
  	<pose>-0.03 -0.115 0.12 0 1.5707 1.5707</pose>
    <collision name="collision">
      <geometry>
        <cylinder>
          <radius>.03</radius>
          <length>.05</length>
        </cylinder>
      </geometry>
    </collision>
    <visual name="visual">
      <geometry>
        <cylinder>
          <radius>.03</radius>
          <length>.05</length>
        </cylinder>
      </geometry>
    </visual>
  </link>

    <link name='left_track'>
      <pose>0.0127 0.115 0.035 0 0 1.5707</pose>
      <collision name='collision'>
        <geometry>
          <box>
            <size>0.05 0.16 0.05</size>
          </box>
        </geometry>
      </collision>
      <visual name='visual'>
        <geometry>
          <box>
            <size>0.05 0.16 0.05</size>
          </box>
        </geometry>
      </visual>
    </link> 

    <link name='right_track'>
      <pose>0.0127 -0.115 0.035 0 0 1.5707</pose>
      <collision name='collision'>
        <geometry>
          <box>
            <size>0.05 0.16 0.05</size>
          </box>
        </geometry>
      </collision>
      <visual name='visual'>
        <geometry>
          <box>
            <size>0.05 0.16 0.05</size>
          </box>
        </geometry>
      </visual>
    </link>   
  
    <link name='left_topbacktrack'>
      <pose>-0.05 0.115 0.08 0.70 0 1.5707</pose>
      <collision name='collision'>
        <geometry>
          <box>
            <size>0.05 0.06 0.12</size>
          </box>
        </geometry>
      </collision>
      <visual name='visual'>
        <geometry>
          <box>
            <size>0.05 0.06 0.12</size>
          </box>
        </geometry>
      </visual>
    </link> 

    <link name='right_topbacktrack'>
      <pose>-0.05 -0.115 0.08 0.70 0 1.5707</pose>
      <collision name='collision'>
        <geometry>
          <box>
            <size>0.05 0.06 0.12</size>
          </box>
        </geometry>
      </collision>
      <visual name='visual'>
        <geometry>
          <box>
            <size>0.05 0.06 0.12</size>
          </box>
        </geometry>
      </visual>
    </link>   
    
    <link name='left_topfronttrack'>
      <pose>0.01 0.115 0.08 -0.90 0 1.5707</pose>
      <collision name='collision'>
        <geometry>
          <box>
            <size>0.05 0.06 0.15</size>
          </box>
        </geometry>
      </collision>
      <visual name='visual'>
        <geometry>
          <box>
            <size>0.05 0.06 0.15</size>
          </box>
        </geometry>
      </visual>
    </link> 

    <link name='right_topfronttrack'>
      <pose>0.01 -0.115 0.08 -0.90 0 1.5707</pose>
      <collision name='collision'>
        <geometry>
          <box>
            <size>0.05 0.06 0.15</size>
          </box>
        </geometry>
      </collision>
      <visual name='visual'>
        <geometry>
          <box>
            <size>0.05 0.06 0.15</size>
          </box>
        </geometry>
      </visual>
    </link> 
    

  <joint type="revolute" name="left_track_hinge">
    <pose>0 0 0 0 0 0</pose>
    <child>left_track</child>
    <parent>chassis</parent>
    <axis>
      <xyz>0 1 0</xyz>
    </axis>
  </joint>
  <joint type="revolute" name="right_track_hinge">
    <pose>0 0 0 0 0 0</pose>
    <child>right_track</child>
    <parent>chassis</parent>
    <axis>
      <xyz>0 1 0</xyz>
    </axis>
  </joint>
  
  <joint type="revolute" name="left_top_hinge">
    <pose>0 0 0 0 0 0</pose>
    <child>left_topwheel</child>
    <parent>chassis</parent>
    <axis>
      <xyz>0 1 0</xyz>
    </axis>
  </joint>
  <joint type="revolute" name="right_top_hinge">
    <pose>0 0 0 0 0 0</pose>
    <child>right_topwheel</child>
    <parent>chassis</parent>
    <axis>
      <xyz>0 1 0</xyz>
    </axis>
  </joint>
  
  <joint type="revolute" name="left_topback_hinge">
    <pose>0 0 0 0 0 0</pose>
    <child>left_topbacktrack</child>
    <parent>chassis</parent>
    <axis>
      <xyz>0 1 0</xyz>
    </axis>
  </joint>
  <joint type="revolute" name="right_topback_hinge">
    <pose>0 0 0 0 0 0</pose>
    <child>right_topbacktrack</child>
    <parent>chassis</parent>
    <axis>
      <xyz>0 1 0</xyz>
    </axis>
  </joint>
  
  <joint type="revolute" name="left_topfront_hinge">
    <pose>0 0 0 0 0 0</pose>
    <child>left_topfronttrack</child>
    <parent>chassis</parent>
    <axis>
      <xyz>0 1 0</xyz>
    </axis>
  </joint>
  <joint type="revolute" name="right_topfront_hinge">
    <pose>0 0 0 0 0 0</pose>
    <child>right_topfronttrack</child>
    <parent>chassis</parent>
    <axis>
      <xyz>0 1 0</xyz>
    </axis>
  </joint>
  
  
  <joint type="revolute" name="left_backwheel_hinge">
    <pose>0 0 0 0 0 0</pose>
    <child>left_backwheel</child>
    <parent>chassis</parent>
    <axis>
      <xyz>0 1 0</xyz>
    </axis>
  </joint>

  <joint type="revolute" name="left_frontwheel_hinge">
    <pose>0 0 0 0 0 0</pose>
    <child>left_frontwheel</child>
    <parent>chassis</parent>
    <axis>
      <xyz>0 1 0</xyz>
    </axis>
  </joint>
  
  <joint type="revolute" name="right_backwheel_hinge">
    <pose>0 0 0 0 0 0</pose>
    <child>right_backwheel</child>
    <parent>chassis</parent>
    <axis>
      <xyz>0 1 0</xyz>
    </axis>
  </joint>

  <joint type="revolute" name="right_frontwheel_hinge">
    <pose>0 0 0 0 0 0</pose>
    <child>right_frontwheel</child>
    <parent>chassis</parent>
    <axis>
      <xyz>0 1 0</xyz>
    </axis>
  </joint>
  
  <joint type="revolute" name="plate_pole1_hinge">
    <pose>0 0 0 0 0 0</pose>
    <child>plate_pole1</child>
    <parent>chassis</parent>
    <axis>
      <xyz>0 1 0</xyz>
    </axis>
  </joint>
  
  <joint type="revolute" name="plate_pole2_hinge">
    <pose>0 0 0 0 0 0</pose>
    <child>plate_pole2</child>
    <parent>chassis</parent>
    <axis>
      <xyz>0 1 0</xyz>
    </axis>
  </joint>
  
  <joint type="revolute" name="plate_pole3_hinge">
    <pose>0 0 0 0 0 0</pose>
    <child>plate_pole3</child>
    <parent>chassis</parent>
    <axis>
      <xyz>0 1 0</xyz>
    </axis>
  </joint>
  
  <joint type="revolute" name="plate_pole4_hinge">
    <pose>0 0 0 0 0 0</pose>
    <child>plate_pole4</child>
    <parent>chassis</parent>
    <axis>
      <xyz>0 1 0</xyz>
    </axis>
  </joint>

  <joint type="revolute" name="plate_hinge">
    <pose>0 0 0 0 0 0</pose>
    <child>plate_pole1</child>
    <parent>plate</parent>  
    <axis>
      <xyz>0 0 1</xyz>
    </axis>
  </joint>
  
  
  </model>
</sdf>

