<?xml version='1.0'?>
<sdf version='1.3'>
  <model name="tank_tread2">
  
    <link name='chassis'>
      <pose>0 0 0.035 0 0 0</pose>
      <collision name='collision'>
        <geometry>
          <box>
            <size>0.13 0.18 0.0445</size>
          </box>
        </geometry>
      </collision>

      <visual name='visual'>
        <geometry>
          <box>
            <size>0.13 0.18 0.0445</size>
          </box>
        </geometry>
      </visual>
    </link> 
  

  <link name="left_topwheel">
  	<pose>-0.03 0.115 0.12 0 1.5707 1.5707</pose>
    <collision name="collision">
      <geometry>
        <cylinder>
          <radius>.03</radius>
          <length>.05</length>
        </cylinder>
      </geometry>
    </collision>
    <visual name="visual">
      <geometry>
        <cylinder>
          <radius>.03</radius>
          <length>.05</length>
        </cylinder>
      </geometry>
    </visual>
  </link>

  <link name="right_topwheel">
  	<pose>-0.03 -0.115 0.12 0 1.5707 1.5707</pose>
    <collision name="collision">
      <geometry>
        <cylinder>
          <radius>.03</radius>
          <length>.05</length>
        </cylinder>
      </geometry>
    </collision>
    <visual name="visual">
      <geometry>
        <cylinder>
          <radius>.03</radius>
          <length>.05</length>
        </cylinder>
      </geometry>
    </visual>
  </link>

    <link name='left_track'>
      <pose>0.0127 0.115 0.035 0 0 1.5707</pose>
      <collision name='collision'>
        <geometry>
          <box>
            <size>0.05 0.16 0.13</size>
          </box>
        </geometry>
      </collision>

      <visual name='visual'>
        <geometry>
          <box>
            <size>0.05 0.16 0.13</size>
          </box>
        </geometry>
      </visual>
    </link> 

    <link name='right_track'>
      <pose>0.0127 -0.115 0.035 0 0 1.5707</pose>
      <collision name='collision'>
        <geometry>
          <box>
            <size>0.05 0.16 0.13</size>
          </box>
        </geometry>
      </collision>

      <visual name='visual'>
        <geometry>
          <box>
            <size>0.05 0.16 0.13</size>
          </box>
        </geometry>
      </visual>
    </link>   
  
  
    <link name='left_topbacktrack'>
      <pose>-0.05 0.115 0.08 0.70 0 1.5707</pose>
      <collision name='collision'>
        <geometry>
          <box>
            <size>0.05 0.08 0.1</size>
          </box>
        </geometry>
      </collision>

      <visual name='visual'>
        <geometry>
          <box>
            <size>0.05 0.08 0.1</size>
          </box>
        </geometry>
      </visual>
    </link> 

    <link name='right_topbacktrack'>
      <pose>-0.05 -0.115 0.08 0.70 0 1.5707</pose>
      <collision name='collision'>
        <geometry>
          <box>
            <size>0.05 0.08 0.1</size>
          </box>
        </geometry>
      </collision>

      <visual name='visual'>
        <geometry>
          <box>
            <size>0.05 0.08 0.1</size>
          </box>
        </geometry>
      </visual>
    </link>   
    
    <link name='left_topfronttrack'>
      <pose>0.01 0.115 0.08 -0.90 0 1.5707</pose>
      <collision name='collision'>
        <geometry>
          <box>
            <size>0.05 0.06 0.15</size>
          </box>
        </geometry>
      </collision>

      <visual name='visual'>
        <geometry>
          <box>
            <size>0.05 0.06 0.15</size>
          </box>
        </geometry>
      </visual>
    </link> 

    <link name='right_topfronttrack'>
      <pose>0.01 -0.115 0.08 -0.90 0 1.5707</pose>
      <collision name='collision'>
        <geometry>
          <box>
            <size>0.05 0.06 0.15</size>
          </box>
        </geometry>
      </collision>

      <visual name='visual'>
        <geometry>
          <box>
            <size>0.05 0.06 0.15</size>
          </box>
        </geometry>
      </visual>
    </link> 
    
  <link name="left_backwheel">
  	<pose>-0.065 0.115 0.035 0 1.5707 1.5707</pose>
    <collision name="collision">
      <geometry>
        <cylinder>
          <radius>.05</radius>
          <length>.05</length>
        </cylinder>
      </geometry>
    </collision>
    <visual name="visual">
      <geometry>
        <cylinder>
          <radius>.05</radius>
          <length>.05</length>
        </cylinder>
      </geometry>
    </visual>
  </link>
  
  <link name="right_backwheel">
  	<pose>-0.065 -0.115 0.035 0 1.5707 1.5707</pose>
    <collision name="collision">
      <geometry>
        <cylinder>
          <radius>.05</radius>
          <length>.05</length>
        </cylinder>
      </geometry>
    </collision>
    <visual name="visual">
      <geometry>
        <cylinder>
          <radius>.05</radius>
          <length>.05</length>
        </cylinder>
      </geometry>
    </visual>
  </link>
  
  
  <link name="left_frontwheel">
  	<pose>0.065 0.115 0.035 0 1.5707 1.5707</pose>
    <collision name="collision">
      <geometry>
        <cylinder>
          <radius>.05</radius>
          <length>.05</length>
        </cylinder>
      </geometry>
    </collision>
    <visual name="visual">
      <geometry>
        <cylinder>
          <radius>.05</radius>
          <length>.05</length>
        </cylinder>
      </geometry>
    </visual>
  </link>

  <link name="right_frontwheel">
  	<pose>0.065 -0.115 0.035 0 1.5707 1.5707</pose>
    <collision name="collision">
      <geometry>
        <cylinder>
          <radius>.05</radius>
          <length>.05</length>
        </cylinder>
      </geometry>
    </collision>
    <visual name="visual">
      <geometry>
        <cylinder>
          <radius>.05</radius>
          <length>.05</length>
        </cylinder>
      </geometry>
    </visual>
  </link>  

  
  <joint type="revolute" name="left_track_hinge">
    <pose>0 0 0 0 0 0</pose>
    <child>left_track</child>
    <parent>chassis</parent>
    <axis>
      <xyz>0 1 0</xyz>
    </axis>
  </joint>
  <joint type="revolute" name="right_track_hinge">
    <pose>0 0 0 0 0 0</pose>
    <child>right_track</child>
    <parent>chassis</parent>
    <axis>
      <xyz>0 1 0</xyz>
    </axis>
  </joint>
  
  <joint type="revolute" name="left_top_hinge">
    <pose>0 0 0 0 0 0</pose>
    <child>left_topwheel</child>
    <parent>chassis</parent>
    <axis>
      <xyz>0 1 0</xyz>
    </axis>
  </joint>
  <joint type="revolute" name="right_top_hinge">
    <pose>0 0 0 0 0 0</pose>
    <child>right_topwheel</child>
    <parent>chassis</parent>
    <axis>
      <xyz>0 1 0</xyz>
    </axis>
  </joint>
  
  <joint type="revolute" name="left_topback_hinge">
    <pose>0 0 0 0 0 0</pose>
    <child>left_toptrack</child>
    <parent>left_backwheel</parent>
    <axis>
      <xyz>0 1 0</xyz>
    </axis>
  </joint>
  <joint type="revolute" name="right_topback_hinge">
    <pose>0 0 0 0 0 0</pose>
    <child>right_toptrack</child>
    <parent>right_backwheel</parent>
    <axis>
      <xyz>0 1 0</xyz>
    </axis>
  </joint>
  
  <joint type="revolute" name="left_topfront_hinge">
    <pose>0 0 0 0 0 0</pose>
    <child>left_toptrack</child>
    <parent>left_frontwheel</parent>
    <axis>
      <xyz>0 1 0</xyz>
    </axis>
  </joint>
  <joint type="revolute" name="right_topfront_hinge">
    <pose>0 0 0 0 0 0</pose>
    <child>right_toptrack</child>
    <parent>right_frontwheel</parent>
    <axis>
      <xyz>0 1 0</xyz>
    </axis>
  </joint>
  
  
  <joint type="revolute" name="left_backwheel_hinge">
    <pose>0 0 0 0 0 0</pose>
    <child>left_backwheel</child>
    <parent>chassis</parent>
    <axis>
      <xyz>0 1 0</xyz>
    </axis>
  </joint>

  <joint type="revolute" name="left_frontwheel_hinge">
    <pose>0 0 0 0 0 0</pose>
    <child>left_frontwheel</child>
    <parent>chassis</parent>
    <axis>
      <xyz>0 1 0</xyz>
    </axis>
  </joint>
  
  <joint type="revolute" name="right_backwheel_hinge">
    <pose>0 0 0 0 0 0</pose>
    <child>right_backwheel</child>
    <parent>chassis</parent>
    <axis>
      <xyz>0 1 0</xyz>
    </axis>
  </joint>

  <joint type="revolute" name="right_frontwheel_hinge">
    <pose>0 0 0 0 0 0</pose>
    <child>right_frontwheel</child>
    <parent>chassis</parent>
    <axis>
      <xyz>0 1 0</xyz>
    </axis>
  </joint>
  
  </model>
</sdf>
<!--
<?xml version='1.0'?>
<sdf version='1.3'>
  <model name="tank_tread">
    <link name='chassis'>
      <pose>0 0 .13 0 0 0</pose>
      <collision name='collision'>
        <geometry>
          <box>
            <size>.25 .18 .13</size>
          </box>
        </geometry>
      </collision>

      <visual name='visual'>
        <geometry>
          <box>
            <size>.25 .18 .13</size>
          </box>
        </geometry>
      </visual>
    </link> 
  
  <link name="left_backwheel">
  	<pose>-0.125 0.115 0.13 0 1.5707 1.5707</pose>
    <collision name="collision">
      <geometry>
        <cylinder>
          <radius>.13</radius>
          <length>.05</length>
        </cylinder>
      </geometry>
    </collision>
    <visual name="visual">
      <geometry>
        <cylinder>
          <radius>.13</radius>
          <length>.05</length>
        </cylinder>
      </geometry>
    </visual>
  </link>
  
  <link name="right_backwheel">
  	<pose>-0.125 -0.115 0.13 0 1.5707 1.5707</pose>
    <collision name="collision">
      <geometry>
        <cylinder>
          <radius>.13</radius>
          <length>.05</length>
        </cylinder>
      </geometry>
    </collision>
    <visual name="visual">
      <geometry>
        <cylinder>
          <radius>.13</radius>
          <length>.05</length>
        </cylinder>
      </geometry>
    </visual>
  </link>
  
  
  <link name="left_frontwheel">
  	<pose>0.125 0.115 0.13 0 1.5707 1.5707</pose>
    <collision name="collision">
      <geometry>
        <cylinder>
          <radius>.13</radius>
          <length>.05</length>
        </cylinder>
      </geometry>
    </collision>
    <visual name="visual">
      <geometry>
        <cylinder>
          <radius>.13</radius>
          <length>.05</length>
        </cylinder>
      </geometry>
    </visual>
  </link>

  <link name="right_frontwheel">
  	<pose>0.125 -0.115 0.13 0 1.5707 1.5707</pose>
    <collision name="collision">
      <geometry>
        <cylinder>
          <radius>.13</radius>
          <length>.05</length>
        </cylinder>
      </geometry>
    </collision>
    <visual name="visual">
      <geometry>
        <cylinder>
          <radius>.13</radius>
          <length>.05</length>
        </cylinder>
      </geometry>
    </visual>
  </link>  


  <joint type="revolute" name="left_backwheel_hinge">
    <pose>0 0 0 0 0 0</pose>
    <child>left_backwheel</child>
    <parent>chassis</parent>
    <axis>
      <xyz>0 1 0</xyz>
    </axis>
  </joint>

  <joint type="revolute" name="left_frontwheel_hinge">
    <pose>0 0 0 0 0 0</pose>
    <child>left_frontwheel</child>
    <parent>chassis</parent>
    <axis>
      <xyz>0 1 0</xyz>
    </axis>
  </joint>
  
  <joint type="revolute" name="right_backwheel_hinge">
    <pose>0 0 0 0 0 0</pose>
    <child>right_backwheel</child>
    <parent>chassis</parent>
    <axis>
      <xyz>0 1 0</xyz>
    </axis>
  </joint>

  <joint type="revolute" name="right_frontwheel_hinge">
    <pose>0 0 0 0 0 0</pose>
    <child>right_frontwheel</child>
    <parent>chassis</parent>
    <axis>
      <xyz>0 1 0</xyz>
    </axis>
  </joint>
  
  </model>
</sdf>
-->
